<robot name="picrawler">
  <!-- Base link -->
  <link name="base_link">
    <visual>
      <geometry>
        <box size="0.1 0.1 0.09"/>  <!-- Body dimensions -->
      </geometry>
      <material name="gray">
        <color rgba="0.5 0.5 0.5 1"/>
      </material>
    </visual>
	<collision>
		<geometry>
			<box size="0.1 0.1 0.1"/>  <!-- Adjust size as needed -->
		</geometry>
	</collision>
    <inertial>
      <mass value="1.0"/>
      <inertia ixx="0.1" ixy="0.0" ixz="0.0" iyy="0.1" iyz="0.0" izz="0.1"/>
    </inertial>
  </link>

  <!-- Front Left Leg -->
  <link name="front_left_upper_leg">
    <visual>
      <geometry>
        <box size="0.09 0.04 0.03"/>  <!-- Upper leg -->
      </geometry>
      <material name="blue">
        <color rgba="0 0 1 1"/>
      </material>
    </visual>
	<collision>
		<geometry>
			<box size="0.09 0.04 0.03"/>  <!-- Upper leg -->
		</geometry>
	</collision>
    <inertial>
      <mass value="0.1"/>
      <inertia ixx="0.01" ixy="0.0" ixz="0.0" iyy="0.01" iyz="0.0" izz="0.01"/>
    </inertial>
  </link>

  <joint name="front_left_shoulder_joint" type="revolute">
    <parent link="base_link"/>
    <child link="front_left_upper_leg"/>
    <origin xyz="0.05 0.05 0" rpy="0 0 0"/>
    <axis xyz="0 0 1"/>
    <limit lower="-1.57" upper="1.57" effort="1.0" velocity="1.0"/>
  </joint>

  <link name="front_left_lower_leg">
    <visual>
      <geometry>
        <box size="0.08 0.04 0.02"/>  <!-- Lower leg -->
      </geometry>
      <material name="red">
        <color rgba="1 0 0 1"/>
      </material>
    </visual>
	<collision>
		<geometry>
			<box size="0.08 0.04 0.02"/>  <!-- Lower leg -->
		</geometry>
	</collision>
    <inertial>
      <mass value="0.05"/>
      <inertia ixx="0.005" ixy="0.0" ixz="0.0" iyy="0.005" iyz="0.0" izz="0.005"/>
    </inertial>
  </link>

  <joint name="front_left_knee_joint" type="revolute">
    <parent link="front_left_upper_leg"/>
    <child link="front_left_lower_leg"/>
    <origin xyz="0.09 0 0" rpy="0 0 0"/>
    <axis xyz="0 1 0"/>
    <limit lower="-1.57" upper="1.57" effort="1.0" velocity="1.0"/>
  </joint>

  <!-- Front Right Leg -->
  <link name="front_right_upper_leg">
    <visual>
      <geometry>
        <box size="0.09 0.04 0.03"/>  <!-- Upper leg -->
      </geometry>
      <material name="blue">
        <color rgba="0 0 1 1"/>
      </material>
    </visual>
	<collision>
		<geometry>
			<box size="0.09 0.04 0.03"/>  <!-- Upper leg -->
		</geometry>
	</collision>
    <inertial>
      <mass value="0.1"/>
      <inertia ixx="0.01" ixy="0.0" ixz="0.0" iyy="0.01" iyz="0.0" izz="0.01"/>
    </inertial>
  </link>

  <joint name="front_right_shoulder_joint" type="revolute">
    <parent link="base_link"/>
    <child link="front_right_upper_leg"/>
    <origin xyz="0.05 -0.05 0" rpy="0 0 0"/>
    <axis xyz="0 0 1"/>
    <limit lower="-1.57" upper="1.57" effort="1.0" velocity="1.0"/>
  </joint>

  <link name="front_right_lower_leg">
    <visual>
      <geometry>
        <box size="0.08 0.04 0.02"/>  <!-- Lower leg -->
      </geometry>
      <material name="red">
        <color rgba="1 0 0 1"/>
      </material>
    </visual>
	<collision>
		<geometry>
			<box size="0.08 0.04 0.02"/>  <!-- Lower leg -->
		</geometry>
	</collision>
    <inertial>
      <mass value="0.05"/>
      <inertia ixx="0.005" ixy="0.0" ixz="0.0" iyy="0.005" iyz="0.0" izz="0.005"/>
    </inertial>
  </link>

  <joint name="front_right_knee_joint" type="revolute">
    <parent link="front_right_upper_leg"/>
    <child link="front_right_lower_leg"/>
    <origin xyz="0.09 0 0" rpy="0 0 0"/>
    <axis xyz="0 1 0"/>
    <limit lower="-1.57" upper="1.57" effort="1.0" velocity="1.0"/>
  </joint>

  <!-- Back Left Leg -->
  <link name="back_left_upper_leg">
    <visual>
      <geometry>
        <box size="0.09 0.04 0.03"/>  <!-- Upper leg -->
      </geometry>
      <material name="blue">
        <color rgba="0 0 1 1"/>
      </material>
    </visual>
	<collision>
		<geometry>
			  <box size="0.09 0.04 0.03"/>  <!-- Upper leg -->
		</geometry>
	</collision>
    <inertial>
      <mass value="0.1"/>
      <inertia ixx="0.01" ixy="0.0" ixz="0.0" iyy="0.01" iyz="0.0" izz="0.01"/>
    </inertial>
  </link>

  <joint name="back_left_shoulder_joint" type="revolute">
    <parent link="base_link"/>
    <child link="back_left_upper_leg"/>
    <origin xyz="-0.05 0.05 0" rpy="0 0 0"/>
    <axis xyz="0 0 1"/>
    <limit lower="-1.57" upper="1.57" effort="1.0" velocity="1.0"/>
  </joint>

  <link name="back_left_lower_leg">
    <visual>
      <geometry>
        <box size="0.08 0.04 0.02"/>  <!-- Lower leg -->
      </geometry>
      <material name="red">
        <color rgba="1 0 0 1"/>
      </material>
    </visual>
	<collision>
		<geometry>
			<box size="0.08 0.04 0.02"/>  <!-- Lower leg -->
		</geometry>
	</collision>
    <inertial>
      <mass value="0.05"/>
      <inertia ixx="0.005" ixy="0.0" ixz="0.0" iyy="0.005" iyz="0.0" izz="0.005"/>
    </inertial>
  </link>

  <joint name="back_left_knee_joint" type="revolute">
    <parent link="back_left_upper_leg"/>
    <child link="back_left_lower_leg"/>
    <origin xyz="0.09 0 0" rpy="0 0 0"/>
    <axis xyz="0 1 0"/>
    <limit lower="-1.57" upper="1.57" effort="1.0" velocity="1.0"/>
  </joint>

  <!-- Back Right Leg -->
  <link name="back_right_upper_leg">
    <visual>
      <geometry>
        <box size="0.09 0.04 0.03"/>  <!-- Upper leg -->
      </geometry>
      <material name="blue">
        <color rgba="0 0 1 1"/>
      </material>
    </visual>
	<collision>
		<geometry>
			<box size="0.09 0.04 0.03"/>  <!-- Upper leg -->
		</geometry>
	</collision>
    <inertial>
      <mass value="0.1"/>
      <inertia ixx="0.01" ixy="0.0" ixz="0.0" iyy="0.01" iyz="0.0" izz="0.01"/>
    </inertial>
  </link>

  <joint name="back_right_shoulder_joint" type="revolute">
    <parent link="base_link"/>
    <child link="back_right_upper_leg"/>
    <origin xyz="-0.05 -0.05 0" rpy="0 0 0"/>
    <axis xyz="0 0 1"/>
    <limit lower="-1.57" upper="1.57" effort="1.0" velocity="1.0"/>
  </joint>

  <link name="back_right_lower_leg">
    <visual>
      <geometry>
        <box size="0.08 0.04 0.02"/>  <!-- Lower leg -->
      </geometry>
      <material name="red">
        <color rgba="1 0 0 1"/>
      </material>
    </visual>
	<collision>
		<geometry>
			<box size="0.08 0.04 0.02"/>  <!-- Lower leg -->
		</geometry>
	</collision>	
    <inertial>
      <mass value="0.05"/>
      <inertia ixx="0.005" ixy="0.0" ixz="0.0" iyy="0.005" iyz="0.0" izz="0.005"/>
    </inertial>
  </link>

  <joint name="back_right_knee_joint" type="revolute">
    <parent link="back_right_upper_leg"/>
    <child link="back_right_lower_leg"/>
    <origin xyz="0.09 0 0" rpy="0 0 0"/>
    <axis xyz="0 1 0"/>
    <limit lower="-1.57" upper="1.57" effort="1.0" velocity="1.0"/>
  </joint>

</robot>
